[2025-02-08T08:55:31.661+0000] {taskinstance.py:1171} INFO - Dependencies all met for <TaskInstance: pipeline_hck_24.extract_data scheduled__2025-02-07T00:00:00+00:00 [queued]>
[2025-02-08T08:55:31.679+0000] {taskinstance.py:1171} INFO - Dependencies all met for <TaskInstance: pipeline_hck_24.extract_data scheduled__2025-02-07T00:00:00+00:00 [queued]>
[2025-02-08T08:55:31.679+0000] {taskinstance.py:1368} INFO - 
--------------------------------------------------------------------------------
[2025-02-08T08:55:31.679+0000] {taskinstance.py:1369} INFO - Starting attempt 1 of 1
[2025-02-08T08:55:31.679+0000] {taskinstance.py:1370} INFO - 
--------------------------------------------------------------------------------
[2025-02-08T08:55:31.686+0000] {taskinstance.py:1389} INFO - Executing <Task(PythonOperator): extract_data> on 2025-02-07 00:00:00+00:00
[2025-02-08T08:55:31.696+0000] {standard_task_runner.py:52} INFO - Started process 431 to run task
[2025-02-08T08:55:31.702+0000] {standard_task_runner.py:79} INFO - Running: ['***', 'tasks', 'run', 'pipeline_hck_24', 'extract_data', 'scheduled__2025-02-07T00:00:00+00:00', '--job-id', '4', '--raw', '--subdir', 'DAGS_FOLDER/P2M3_RizkySP_DAG.py', '--cfg-path', '/tmp/tmpv2a68t4r', '--error-file', '/tmp/tmpexvae4my']
[2025-02-08T08:55:31.703+0000] {standard_task_runner.py:80} INFO - Job 4: Subtask extract_data
[2025-02-08T08:55:31.812+0000] {task_command.py:371} INFO - Running <TaskInstance: pipeline_hck_24.extract_data scheduled__2025-02-07T00:00:00+00:00 [running]> on host b33620135048
[2025-02-08T08:55:32.018+0000] {taskinstance.py:1583} INFO - Exporting the following env vars:
AIRFLOW_CTX_DAG_OWNER=RizkySP
AIRFLOW_CTX_DAG_ID=pipeline_hck_24
AIRFLOW_CTX_TASK_ID=extract_data
AIRFLOW_CTX_EXECUTION_DATE=2025-02-07T00:00:00+00:00
AIRFLOW_CTX_TRY_NUMBER=1
AIRFLOW_CTX_DAG_RUN_ID=scheduled__2025-02-07T00:00:00+00:00
[2025-02-08T08:55:32.067+0000] {base.py:68} INFO - Using connection ID '***_postgres' for task execution.
[2025-02-08T08:55:32.105+0000] {taskinstance.py:1902} ERROR - Task failed with exception
Traceback (most recent call last):
  File "/home/airflow/.local/lib/python3.7/site-packages/pandas/io/sql.py", line 2056, in execute
    cur.execute(*args, **kwargs)
psycopg2.errors.UndefinedTable: relation "raw_data" does not exist
LINE 1: SELECT * FROM raw_data
                      ^


The above exception was the direct cause of the following exception:

Traceback (most recent call last):
  File "/home/airflow/.local/lib/python3.7/site-packages/airflow/operators/python.py", line 171, in execute
    return_value = self.execute_callable()
  File "/home/airflow/.local/lib/python3.7/site-packages/airflow/operators/python.py", line 189, in execute_callable
    return self.python_callable(*self.op_args, **self.op_kwargs)
  File "/opt/airflow/dags/P2M3_RizkySP_DAG.py", line 26, in extract
    data_raw = pd.read_sql('SELECT * FROM raw_data', source_conn)
  File "/home/airflow/.local/lib/python3.7/site-packages/pandas/io/sql.py", line 608, in read_sql
    chunksize=chunksize,
  File "/home/airflow/.local/lib/python3.7/site-packages/pandas/io/sql.py", line 2116, in read_query
    cursor = self.execute(*args)
  File "/home/airflow/.local/lib/python3.7/site-packages/pandas/io/sql.py", line 2068, in execute
    raise ex from exc
pandas.io.sql.DatabaseError: Execution failed on sql 'SELECT * FROM raw_data': relation "raw_data" does not exist
LINE 1: SELECT * FROM raw_data
                      ^

[2025-02-08T08:55:32.602+0000] {taskinstance.py:1412} INFO - Marking task as FAILED. dag_id=pipeline_hck_24, task_id=extract_data, execution_date=20250207T000000, start_date=20250208T085531, end_date=20250208T085532
[2025-02-08T08:55:32.802+0000] {standard_task_runner.py:97} ERROR - Failed to execute job 4 for task extract_data (Execution failed on sql 'SELECT * FROM raw_data': relation "raw_data" does not exist
LINE 1: SELECT * FROM raw_data
                      ^
; 431)
[2025-02-08T08:55:32.826+0000] {local_task_job.py:156} INFO - Task exited with return code 1
[2025-02-08T08:55:32.868+0000] {local_task_job.py:279} INFO - 0 downstream tasks scheduled from follow-on schedule check
